Workbook

Sheet DASHBOARD
B2: CONTROLE DE GASTO FINANCEIRO
B3: PAINEL PESSOAL • GASTOS • INVESTIMENTOS • META DOS R$ 100 MIL
B5: MÊS DE ANÁLISE | C5: 46266 | E5: RENDA MENSAL | F5: ='CONTROLE LANCAMENTOS'!D25 -> 1535
B7: DISPONÍVEL PARA USAR NO MÊS | E7: QUANTIDADE DE DESPESAS | H7: PATRIMÔNIO TOTAL
B8: =F5-C14-C15 -> 0 | E8: =COUNTIF('CONTROLE LANCAMENTOS'!$J$18:$J$47,"DESPESA") -> 15 | H8: =PATRIMÔNIO!$J$9 -> 31835.24
B12: RESUMO DO MÊS | E12: ONDE SEU DINHEIRO ESTÁ INDO
E13: CATEGORIA | F13: VALOR
B14: DESPESAS DO MÊS | C14: ='CONTROLE LANCAMENTOS'!$K$50 -> 1385 | E14: Moradia | F14: =SUMIFS('CONTROLE LANCAMENTOS'!$K$18:$K$47,'CONTROLE LANCAMENTOS'!$I$18:$I$47,E14,'CONTROLE LANCAMENTOS'!$J$18:$J$47,"DESPESA") -> 1000
B15: INVESTIMENTOS DO MÊS | C15: =PATRIMÔNIO!$J$10 -> 150 | E15: Alimentação | F15: =SUMIFS('CONTROLE LANCAMENTOS'!$K$18:$K$47,'CONTROLE LANCAMENTOS'!$I$18:$I$47,E15,'CONTROLE LANCAMENTOS'!$J$18:$J$47,"DESPESA") -> 0
B16: PATRIMÔNIO INVESTIDO | C16: =PATRIMÔNIO!C28 -> 31835.24 | E16: Transporte | F16: =SUMIFS('CONTROLE LANCAMENTOS'!$K$18:$K$47,'CONTROLE LANCAMENTOS'!$I$18:$I$47,E16,'CONTROLE LANCAMENTOS'!$J$18:$J$47,"DESPESA") -> 210
B17: META R$ 100 MIL | C17: =PATRIMÔNIO!B28 -> 100000 | E17: Contas | F17: =SUMIFS('CONTROLE LANCAMENTOS'!$K$18:$K$47,'CONTROLE LANCAMENTOS'!$I$18:$I$47,E17,'CONTROLE LANCAMENTOS'!$J$18:$J$47,"DESPESA") -> 50
B18: FALTA PARA A META | C18: =PATRIMÔNIO!D28 -> 68164.76 | E18: Saúde | F18: =SUMIFS('CONTROLE LANCAMENTOS'!$K$18:$K$47,'CONTROLE LANCAMENTOS'!$I$18:$I$47,E18,'CONTROLE LANCAMENTOS'!$J$18:$J$47,"DESPESA") -> 100
B19: META CONCLUÍDA | C19: =PATRIMÔNIO!F28 -> 0.3183524 | E19: Lazer | F19: =SUMIFS('CONTROLE LANCAMENTOS'!$K$18:$K$47,'CONTROLE LANCAMENTOS'!$I$18:$I$47,E19,'CONTROLE LANCAMENTOS'!$J$18:$J$47,"DESPESA") -> 0
B20: MENSAL NECESSÁRIO | C20: =PATRIMÔNIO!G28 -> 1624.4944 | E20: Compras | F20: =SUMIFS('CONTROLE LANCAMENTOS'!$K$18:$K$47,'CONTROLE LANCAMENTOS'!$I$18:$I$47,E20,'CONTROLE LANCAMENTOS'!$J$18:$J$47,"DESPESA") -> 0
E21: Assinaturas | F21: =SUMIFS('CONTROLE LANCAMENTOS'!$K$18:$K$47,'CONTROLE LANCAMENTOS'!$I$18:$I$47,E21,'CONTROLE LANCAMENTOS'!$J$18:$J$47,"DESPESA") -> 0
E22: Outros | F22: =SUMIFS('CONTROLE LANCAMENTOS'!$K$18:$K$47,'CONTROLE LANCAMENTOS'!$I$18:$I$47,E22,'CONTROLE LANCAMENTOS'!$J$18:$J$47,"DESPESA") -> 25
H28: ACESSO RÁPIDO
H29: =HYPERLINK("#'CONTROLE LANCAMENTOS'!A1","→ CONTROLE LANÇAMENTOS") -> → CONTROLE LANÇAMENTOS
H30: =HYPERLINK("#'PATRIMÔNIO'!A1","→ PATRIMÔNIO") -> → PATRIMÔNIO
H31: =HYPERLINK("#'APOSENTADORIA'!A1","→ APOSENTADORIA") -> → APOSENTADORIA
E41: Casais Inteligentes Enriquecem Juntos é um livro escrito por Gustavo Cerbasi que aborda a importância do planejamento financeiro para casais. A mensagem central do livro é que o sucesso financeiro em um relacionamento depende de uma comunicação clara, objetivos comuns e planejamento conjunto. Aqui estão alguns pontos chave:
E45: 1. **Comunicação Financeira:** Cerbasi enfatiza a importância de conversar abertamente sobre dinheiro. Casais devem discutir suas expectativas, sonhos e preocupações financeiras para evitar mal-entendidos e conflitos.
E48: 2. **Planejamento Conjunto:** É crucial que ambos os parceiros estejam envolvidos no planejamento financeiro. Isso inclui a criação de um orçamento, a definição de metas de curto e longo prazo e a revisão regular das finanças.
E52: 3. **Investimentos e Poupança:** O livro aconselha sobre como investir de maneira inteligente e diversificada. Cerbasi explica a importância de poupar e investir cedo, aproveitando o poder dos juros compostos.
E55: 4. **Educação Financeira:** Cerbasi destaca a importância da educação financeira contínua. Casais devem se informar sobre finanças pessoais para tomar decisões mais informadas e eficazes.
E59: 5. **Adaptação às Mudanças:** O livro também fala sobre a necessidade de adaptação a diferentes fases da vida e como essas mudanças podem afetar o planejamento financeiro do casal.

Sheet CONTROLE LANCAMENTOS
A2: CONTROLE DE GASTO FINANCEIRO
K14: Atualizada em 20/06/2024 | Q14: Ganho 10/2026 | Z14: Gastos 10/2025
A15: ENTRADAS | G15: DESPESAS | Q15: Janeiro | T15: Fevereiro | W15: Março | Z15: Janeiro | AC15: Fevereiro | AF15: Março
A16: DESCRIÇÃO | D16: VALOR | G16: DATA | H16: DESCRIÇÃO | I16: CATEGORIA | J16: TIPO | K16: VALOR | L16: FORMA DE PAGAMENTO | M16: STATUS | N16: =IF(G16="","",TEXT(G16,"mm/yyyy")) -> DATA | Q16: Total: | R16: 7717.91 | T16: Total: | U16: 4760 | W16: Total: | X16: 6665 | Z16: Dia de Reis(6) | AA16: Aniversário de mãe (28) | AC16: Aniversário de pai (1) | AD16: Carnaval (13) | AF16: Aniversário da minha namorada (15) | AG16: Páscoa
A17: SALÁRIO LÍQUIDO DELE [JANDERSON ] | D17: 1535 | G17: ESSENCIAIS | N17: =IF(G17="","",TEXT(G17,"mm/yyyy")) -> ESSENCIAIS
A18: OUTRAS ENTRADAS 01 (AVON, UBER...) | D18: 0 | H18: MORADIA (ALUGUEL/FINANCIAMENTO) | I18: Moradia | J18: DESPESA | K18: 1000 | M18: PENDENTE | N18: =IF(G18="","",TEXT(G18,"mm/yyyy")) | AG18: Sexta-feira santa
A19: OUTRAS ENTRADAS 02 (COMISSÕES, BÔNUS...) | D19: 0 | H19: CONDOMÍNIO | I19: Contas | J19: DESPESA | K19: 0 | M19: PAGO | N19: =IF(G19="","",TEXT(G19,"mm/yyyy"))
A20: OUTRAS ENTRADAS 03 (ALUGUEL, AULAS...) | D20: 0 | H20: SUPERMERCADO (VALOR MÉDIO) | I20: Alimentação | J20: DESPESA | K20: 0 | M20: PENDENTE | N20: =IF(G20="","",TEXT(G20,"mm/yyyy"))
A21: SALÁRIO LÍQUIDO DELA [MYLLENE ] | D21: 0 | H21: ÁGUA (INCLUSO NO CONDOMÍNIO?) | I21: Contas | J21: DESPESA | K21: 0 | M21: PENDENTE | N21: =IF(G21="","",TEXT(G21,"mm/yyyy")) | Z21: Total: | AA21: 198 | AC21: Total: | AD21: 220 | AF21: Total: | AG21: 1686
A22: OUTRAS ENTRADAS 01 (AVON, UBER...) | D22: 0 | H22: LUZ (INCLUSO NO CONDOMÍNIO?) | I22: Contas | J22: DESPESA | K22: 0 | M22: PENDENTE | N22: =IF(G22="","",TEXT(G22,"mm/yyyy"))
A23: OUTRAS ENTRADAS 02 (COMISSÕES, BÔNUS...) | D23: 0 | H23: GÁS (INCLUSO NO CONDOMÍNIO?) | I23: Contas | J23: DESPESA | K23: 0 | M23: PENDENTE | N23: =IF(G23="","",TEXT(G23,"mm/yyyy"))
A24: OUTRAS ENTRADAS 03 (ALUGUEL, AULAS...) | D24: 0 | H24: IPTU (INCLUSO NO CONDOMÍNIO?) | I24: Contas | J24: DESPESA | K24: 0 | M24: PENDENTE | N24: =IF(G24="","",TEXT(G24,"mm/yyyy")) | Q24: Abril | T24: Maio | W24: Junho | Z24: Abril | AC24: Maio | AF24: Junho
A25: TOTAL DE ENTRADAS | D25: =SUM(D17:D24) -> 1535 | H25: PLANO DE SAÚDE (INCLUSO NOS BENEFÍCIOS DO TRABALHO?) | I25: Saúde | J25: DESPESA | K25: 100 | M25: PENDENTE | N25: =IF(G25="","",TEXT(G25,"mm/yyyy")) | Q25: Total: | R25: 1530 | T25: Total: | U25: 1535 | W25: Total: | X25: 1535 | Z25: 1 ano de namoro | AF25: Aniversário da Sogra(2) | AG25: São João(24)
H26: SEGURO DE VIDA (INCLUSO NOS BENEFÍCIOS DO TRABALHO?) | I26: Outros | J26: DESPESA | K26: 0 | M26: PENDENTE | N26: =IF(G26="","",TEXT(G26,"mm/yyyy"))
H27: OUTRAS DESPESAS ESSENCIAIS 01 | I27: Outros | J27: DESPESA | K27: 0 | M27: PENDENTE | N27: =IF(G27="","",TEXT(G27,"mm/yyyy")) | AF27: Dia dos namorados (12)
H28: OUTRAS DESPESAS ESSENCIAIS 02 | I28: Outros | J28: DESPESA | K28: 0 | M28: PENDENTE | N28: =IF(G28="","",TEXT(G28,"mm/yyyy"))
A29: SE SUA PLANILHA ESTIVER CORRETA, TODO MÊS VAI TE SOBRAR ESTE VALOR PARA INVESTIR: | D29: =D25-K50 -> 150 | H29: OUTRAS DESPESAS ESSENCIAIS 03 | I29: Outros | J29: DESPESA | K29: 0 | M29: PENDENTE | N29: =IF(G29="","",TEXT(G29,"mm/yyyy"))
G30: NÃO ESSENCIAIS | N30: =IF(G30="","",TEXT(G30,"mm/yyyy")) -> NÃO ESSENCIAIS
A31: NESTE CENÁRIO, SUA RESERVA DE EMERGÊNCIA IDEAL SERIA NO VALOR DE: | D31: =K50*12 -> 16620 | H31: CARTÃO DE CRÉDITO (EVITE USAR!) | I31: Outros | J31: DESPESA | K31: 0 | N31: =IF(G31="","",TEXT(G31,"mm/yyyy")) | Z31: Total: | AA31: 473.5 | AC31: Total: | AD31: 1440 | AF31: Total: | AG31: 824
H32: COMBUSTÍVEL | I32: Transporte | J32: DESPESA | K32: 150 | M32: PENDENTE | N32: =IF(G32="","",TEXT(G32,"mm/yyyy"))
H33: FARMÁCIA | I33: Saúde | J33: DESPESA | K33: 0 | N33: =IF(G33="","",TEXT(G33,"mm/yyyy"))
H34: GASTOS COM ANIMAIS | I34: Outros | J34: DESPESA | K34: 0 | N34: =IF(G34="","",TEXT(G34,"mm/yyyy")) | Q34: Julho | T34: Agosto | W34: Setembro | Z34: Julho | AC34: Agosto | AF34: Setembro
H35: GASTOS IMPREVISTOS (VALOR MÉDIO) | I35: Outros | J35: DESPESA | K35: 0 | N35: =IF(G35="","",TEXT(G35,"mm/yyyy")) | Q35: Total: | R35: 3573.36 | T35: Total: | U35: 290 | W35: Total: | X35: 250 | AC35: Aniversário do sogro
H36: GASTOS COM TRANSPORTE (ÔNIBUS/TREM/UBER) | I36: Transporte | J36: DESPESA | K36: 0 | N36: =IF(G36="","",TEXT(G36,"mm/yyyy"))
H37: GASTOS COM VEÍCULO (CARRO/MOTO/FINANCIAMENTO) | I37: Transporte | J37: DESPESA | K37: 0 | N37: =IF(G37="","",TEXT(G37,"mm/yyyy"))
H38: INTERNET RESIDENCIAL | I38: Contas | J38: DESPESA | K38: 0 | M38: PENDENTE | N38: =IF(G38="","",TEXT(G38,"mm/yyyy"))
H39: NETFLIX/AMAZON/NET | I39: Assinaturas | J39: DESPESA | K39: 0 | N39: =IF(G39="","",TEXT(G39,"mm/yyyy"))
H40: PADARIA/FEIRA | I40: Alimentação | J40: DESPESA | K40: 0 | M40: PENDENTE | N40: =IF(G40="","",TEXT(G40,"mm/yyyy"))
H41: SAÍDAS/CINEMA/LAZER | I41: Lazer | J41: DESPESA | K41: 0 | M41: PENDENTE | N41: =IF(G41="","",TEXT(G41,"mm/yyyy")) | Z41: Total: | AA41: 170 | AC41: Total: | AD41: 1917 | AF41: Total: | AG41: 145
H42: SALÃO/MANICURE/DEPILAÇÃO | I42: Outros | J42: DESPESA | K42: 0 | M42: PENDENTE | N42: =IF(G42="","",TEXT(G42,"mm/yyyy"))
H43: TARIFAS BANCÁRIAS (PEÇA ISENÇÃO DESSAS TAXAS NO BANCO!) | I43: Contas | J43: DESPESA | K43: 0 | N43: =IF(G43="","",TEXT(G43,"mm/yyyy"))
H44: TELEFONIA/CELULAR | I44: Contas | J44: DESPESA | K44: 50 | M44: PENDENTE | N44: =IF(G44="","",TEXT(G44,"mm/yyyy")) | Q44: Outubro | T44: Novembro | W44: Dezembro | Z44: Outubro | AC44: Novembro | AF44: Dezembro
H45: ÓLEO DA MOTO | I45: Transporte | J45: DESPESA | K45: 60 | M45: PENDENTE | N45: =IF(G45="","",TEXT(G45,"mm/yyyy")) | Q45: Total: | T45: Total: | W45: Total: | AC45: Finado(2) | AF45: Natal(25) | AG45: Final de anos
H46: CORTE DE CABELO | I46: Outros | J46: DESPESA | K46: 25 | M46: PENDENTE | N46: =IF(G46="","",TEXT(G46,"mm/yyyy"))
H47: OUTRAS DESPESAS 03 (ITENS DIVERSOS) | I47: Outros | K47: 0 | M47: PENDENTE | N47: =IF(G47="","",TEXT(G47,"mm/yyyy"))
H48: TOTAL DE DESPESAS ESSENCIAIS | K48: =SUM(K18:K29) -> 1100 | N48: =IF(G48="","",TEXT(G48,"mm/yyyy"))
H49: TOTAL DE DESPESAS NÃO ESSENCIAIS | K49: =SUM(K31:K47) -> 285 | N49: =IF(G49="","",TEXT(G49,"mm/yyyy"))
H50: TOTAL GERAL DE DESPESAS | K50: =SUM(K48:K49) -> 1385 | N50: =IF(G50="","",TEXT(G50,"mm/yyyy")) | Z50: Total: | AC50: Total: | AF50: Total:
Q52: =R16+U16+X16+R25+U25+X25+R35+U35+X35+R45+U45+X45 -> 27856.27 | U52: =Q52-Z52 -> 20782.77 | Z52: =AA21+AD21+AG21+AA31+AD31+AG31+AA41+AD41+AG41+AA50+AD50+AG50 -> 7073.5 | AF52: =Z52/12 -> 589.45833
AF54: Media

Sheet PATRIMÔNIO
A1: ATIVO / INVESTIMENTO | B1: CLASSE | C1: VALOR ATUAL | F1: DATA | G1: OBSERVAÇÃO | I1: IDEAL | J1: Percentual atual | K1: Investimento
A2: GGRC11 | B2: FIIs | E2: =J9 -> 31835.24 | F2: 46291 | G2: Alocado no C6 invest e Na Binance | H2: K (22%) | I2: 0.22 | J2: 0.22 | K2: =($J$9+$J$10)*J2 -> 7036.7528 | N2: VALOR APLICADO | O2: =$J$9 -> 31835.24
A3: XPML11 | B3: FIIs | H3: R (25%) | I3: 0.25 | J3: 0.25 | K3: =($J$9+$J$10)*J3 -> 7996.31 | N3: SALDO BRUTO | O3: 31896.29
A4: CPTS11 | B4: FIIs | H4: A (25%) | I4: 0.25 | J4: 0.25 | K4: =($J$9+$J$10)*J4 -> 7996.31 | N4: Ganho de capital | O4: =O3-O2 -> 61.05
A5: GARE11 | B5: FIIs | H5: K (3%) | I5: 0.03 | J5: 0.03 | K5: =($J$9+$J$10)*J5 -> 959.5572 | N5: VARIAÇÃO | O5: =O4/O2 -> 0.0019176862
A6: VGHF11 | B6: FIIs | H6: E (25%) | I6: 0.25 | J6: 0.25 | K6: =($J$9+$J$10)*J6 -> 7996.31
A7: NEWL11 | B7: FIIs | N7: PROVENTOS PAGOS
A8: HGLG11 | B8: FIIs | N8: Total:
A9: BTLG11 | B9: FIIs | I9: Patrimônio total | J9: 31835.24 | N9: 2585.83
A10: TAEE11 | B10: Ações | I10: Aporte mensal | J10: 150 | N10: PERFORMANCE | O10: CAGR
A11: KLBN11 | B11: Ações | N11: =(N9+O4)/O2 -> 0.083143083 | O11: =((N9+O3)/O2)^(1/1)-1 -> 0.083143083
A12: KLBN4 | B12: Ações
A13: ITSA4 | B13: Ações
A14: CMIG4 | B14: Ações | H14: META: alcançar R$1000 de dividendos mensais
A15: SAPR4 | B15: Ações | H15: K | I15: R | J15: A | K15: K | L15: E
A16: BBAS3 | B16: Ações | H16: caixa | I16: reits | J16: ações br | K16: criptomoedas | L16: exterior stocks
A17: CXSE3 | B17: Ações | H17: CDB C6 invest | I17: GGRC11 | J17: TAEE11 | K17: BTC | L17: IVVB11
A18: AURE3 | B18: Ações | I18: XPML11 | J18: KLBN11 | K18: ETH | L18: NASD11
A19: BTC | B19: Cripto | I19: CPTS11 | J19: KLBN4
A20: ETH | B20: Cripto | I20: GARE11 | J20: ITSA4
A21: IVVB11 | B21: Exterior | I21: VGHF11 | J21: CMIG4
A22: NASD11 | B22: Exterior | I22: NEWL11 | J22: SAPR4
A23: C6 CDB | B23: Renda Fixa | I23: HGLG11 | J23: BBAS3
I24: BTLG11 | J24: CXSE3
J25: AURE3
J26: BBSE3
A27: META | B27: VALOR ALVO | C27: VALOR ATUAL | D27: FALTA | E27: PRAZO | F27: % CONCLUÍDO | G27: MENSAL NECESSÁRIO | H27: Começamos em: | J27: 21/08/2023
A28: R$ 100 mil investidos até os 24 anos | B28: 100000 | C28: =J9 -> 31835.24 | D28: =MAX(B28-C28,0) -> 68164.76 | E28: 47269 | F28: =IFERROR(C28/B28,0) -> 0.3183524 | G28: =IFERROR(PMT((1+10%)^(1/12)-1,DATEDIF(TODAY(),E28,"m"),C28,-B28,0),0) -> 1624.4944
D29: =MAX(B29-C29,0) -> 0 | F29: =IFERROR(C29/B29,0) -> 0 | G29: =IFERROR(PMT((1+10%)^(1/12)-1,DATEDIF(TODAY(),E29,"m"),C29,-B29,0),0) -> 0
D30: =MAX(B30-C30,0) -> 0 | F30: =IFERROR(C30/B30,0) -> 0 | G30: =IFERROR(PMT((1+10%)^(1/12)-1,DATEDIF(TODAY(),E30,"m"),C30,-B30,0),0) -> 0
D31: =MAX(B31-C31,0) -> 0 | F31: =IFERROR(C31/B31,0) -> 0 | G31: =IFERROR(PMT((1+10%)^(1/12)-1,DATEDIF(TODAY(),E31,"m"),C31,-B31,0),0) -> 0
D32: =MAX(B32-C32,0) -> 0 | F32: =IFERROR(C32/B32,0) -> 0 | G32: =IFERROR(PMT((1+10%)^(1/12)-1,DATEDIF(TODAY(),E32,"m"),C32,-B32,0),0) -> 0
D33: =MAX(B33-C33,0) -> 0 | F33: =IFERROR(C33/B33,0) -> 0 | G33: =IFERROR(PMT((1+10%)^(1/12)-1,DATEDIF(TODAY(),E33,"m"),C33,-B33,0),0) -> 0
D34: =MAX(B34-C34,0) -> 0 | F34: =IFERROR(C34/B34,0) -> 0 | G34: =IFERROR(PMT((1+10%)^(1/12)-1,DATEDIF(TODAY(),E34,"m"),C34,-B34,0),0) -> 0
D35: =MAX(B35-C35,0) -> 0 | F35: =IFERROR(C35/B35,0) -> 0 | G35: =IFERROR(PMT((1+10%)^(1/12)-1,DATEDIF(TODAY(),E35,"m"),C35,-B35,0),0) -> 0
D36: =MAX(B36-C36,0) -> 0 | F36: =IFERROR(C36/B36,0) -> 0 | G36: =IFERROR(PMT((1+10%)^(1/12)-1,DATEDIF(TODAY(),E36,"m"),C36,-B36,0),0) -> 0
D37: =MAX(B37-C37,0) -> 0 | F37: =IFERROR(C37/B37,0) -> 0 | G37: =IFERROR(PMT((1+10%)^(1/12)-1,DATEDIF(TODAY(),E37,"m"),C37,-B37,0),0) -> 0
D38: =MAX(B38-C38,0) -> 0 | F38: =IFERROR(C38/B38,0) -> 0 | G38: =IFERROR(PMT((1+10%)^(1/12)-1,DATEDIF(TODAY(),E38,"m"),C38,-B38,0),0) -> 0
D39: =MAX(B39-C39,0) -> 0 | F39: =IFERROR(C39/B39,0) -> 0 | G39: =IFERROR(PMT((1+10%)^(1/12)-1,DATEDIF(TODAY(),E39,"m"),C39,-B39,0),0) -> 0
D40: =MAX(B40-C40,0) -> 0 | F40: =IFERROR(C40/B40,0) -> 0 | G40: =IFERROR(PMT((1+10%)^(1/12)-1,DATEDIF(TODAY(),E40,"m"),C40,-B40,0),0) -> 0
...

Sheet APOSENTADORIA
A1: APOSENTADORIA • LIBERDADE FINANCEIRA
B4: Projeção do patrimônio, aportes e renda futura
B17: CALCULADORA - ESTIMANDO O PATRIMÔNIO INVESTIDO *
B19: INFORMAÇÕES PARA PREENCHER | H19: PREENCHA ABAIXO | I19: OBSERVAÇÕES
B20: QUAL SUA IDADE HOJE ? | H20: 22 | I20: ~ Só preencha o número
B21: COM QUAL IDADE PRETENDE SE APOSENTAR ? | H21: 24 | I21: ~Só preencha o número. Precisa ser maior do que a idade de hoje
B22: QUAL O VALOR DO SEU PATRIMÔNIO INVESTIDO HOJE ? | H22: 32000 | I22: - Valor em R$
B23: QUAL O VALOR MENSAL QUE DEVERÁ INVESTIR ? | H23: =PMT(((H24+1)^(1/12))-1,(H21-H20)*12,H22,-H30,0) -> 2326.9301 | I23: - Valor em R$
B24: QUAL RENTABILIDADE REAL ESPERADA (AO ANO E DESCONTADA A INFLAÇÃO) ? | H24: 0.1 | I24: - Valor em percentual, por exemplo, 3%
J28: ATENÇÃO: PARA PRESERVAR SEU PODER DE COMPRA
H29: VALOR ACUMULADO | J29: NO TEMPO, ATUALIZE SEUS APORTES PELA INFLAÇÃO.
B30: VALOR ACUMULADO ATÉ A DATA DA APOSENTADORIA💰👉🏽 | H30: 100000
B31: * Preencher apenas as células em amarelo.
G34: Renda Mensal | H34: Taxa
G35: 1000 | H35: 0.01
G37: massa crítica
G38: =G35/H35 -> 100000
E42: Massa crítica | H42: =G38 -> 100000
E43: Mês | F43: Taxa Bruta | H43: Valor Bruto | I43: Inflação | J43: Valor tirando a inflação
E44: 1 | F44: 0.01 | H44: =FVSCHEDULE(H42,F44) -> 101000 | I44: 0.002 | J44: =H44/(1+I44) -> 100808.38
E45: 2 | F45: 0.01 | H45: =FVSCHEDULE(H44,F45) -> 101202 | I45: 0.002 | J45: =H45/(1+I45) -> 101000
E46: 3 | F46: 0.01 | H46: =FVSCHEDULE(H45,F46) -> 101202 | I46: 0.002 | J46: =H46/(1+I46) -> 101000
E47: 4 | F47: 0.01 | H47: =FVSCHEDULE(H46,F47) -> 101202 | I47: 0.002 | J47: =H47/(1+I47) -> 101000
E48: 5 | F48: 0.01 | H48: =FVSCHEDULE(H47,F48) -> 101202 | I48: 0.002 | J48: =H48/(1+I48) -> 101000
E49: Valor do reinvestimento da Inflação
E50: =G38*(1+0.2%) -> 100200
E53: 0 cálculo da massa crítica necessária não é complicado. Em primeiro lugar, vocês devem estimar o
E54: rendimento que seria obtido em uma aplicação financeira segura. No Brasil de hoje (e, provavelmente,
E55: dos próximos anos), as aplicações financeiras mais seguras, como CDBs e fundos de renda fixa,
E56: rendem cerca de 0,4% líquido ao mês10, já descontados o imposto de renda e a inflação. Basta dividir
E57: a renda desejada pela taxa de juros obtida e terão a meta desejada de massa crítica. No exemplo:
E59: R$ 3.000,00÷0,004 = R$ 750.000,00
E61: Percebam que 0,4% de R$ 750.000,00 é igual a R$ 3.000,00. Como estamos descontando a
E62: inflação, sempre teremos o valor da poupança atualizado, que vai gerar uma renda equivalente a R$
E63: 3.000,00.
E64: Entendam esse raciocínio pelo seguinte exemplo:
E65: 1) R$ 750.000,00, aplicados em um fundo balanceado conservador, renderam 0,6% de juros
E66: durante o mês, já descontados o imposto de renda e a taxa de administração do banco11. Esse
... E90: vários outros com inflação igual a zero.
